[2025-05-11 22:10:02.469821] 开始准备数据 user_id=unscmol, job_id=16
使用参数文件: C:\Users\ZY\Desktop\Forecaster\config\job_config\job_params_unscmol_16.json
场站 cl: 训练集大小 = 28032, 测试集大小 = 7008
场站 js: 训练集大小 = 28032, 测试集大小 = 7008
场站 jz: 训练集大小 = 28032, 测试集大小 = 7008
场站 lym: 训练集大小 = 28032, 测试集大小 = 7008
场站 qss: 训练集大小 = 28032, 测试集大小 = 7008
场站 wtl: 训练集大小 = 28032, 测试集大小 = 7008
场站 zh: 训练集大小 = 28032, 测试集大小 = 7008
[2025-05-11 22:10:02.498824] 数据准备失败 ❌: [Errno 2] No such file or directory: '../data/user_data/unscmol/download_data/temp_trainset_unscmol_1_16.joblib'
详细错误信息如下：
Traceback (most recent call last):
  File "C:\Users\ZY\Desktop\Forecaster\scripts\prepare_data.py", line 54, in <module>
    Generate_Data.execute_task()
  File "C:\Users\ZY\Desktop\Forecaster\web_interface\..\src\data_manager\data_send_src.py", line 90, in execute_task
    return task_mapping[task_id]()
  File "C:\Users\ZY\Desktop\Forecaster\web_interface\..\src\data_manager\data_send_src.py", line 42, in gen_task1
    joblib.dump(train_data_dic, '../data/user_data/{}/download_data/temp_trainset_{}_{}_{}.joblib'.format(self.user_id, self.user_id, self.task_id, self.job_number))
  File "C:\ProgramData\Anaconda3\envs\pytorch_gpu\lib\site-packages\joblib\numpy_pickle.py", line 552, in dump
    with open(filename, 'wb') as f:
FileNotFoundError: [Errno 2] No such file or directory: '../data/user_data/unscmol/download_data/temp_trainset_unscmol_1_16.joblib'
